<?xml version="1.0" ?>
<robot name="partnet_c3bb5f3c842a6c2d178e7d331e641179">
	<link name="base"/>

	<link name="link_0">
		<visual name="door">
			<origin xyz="0.6430403380134146 0.42593899369239807 -0.5477944794777341"/>
			<geometry>
				<mesh filename="new_door_space.obj"/>
			</geometry>
		</visual>
		<collision>
			<origin xyz="0.6430403380134146 0.42593899369239807 -0.5477944794777341"/>
			<geometry>
				<mesh filename="new_door_space.obj"/>
			</geometry>
		</collision>
		<visual name="door_handle">
			<origin xyz="0.6430403380134146 0.42593899369239807 -0.5477944794777341"/>
			<geometry>
				<mesh filename="new_door_handle_space.obj"/>
			</geometry>
		</visual>
		<collision>
			<origin xyz="0.6430403380134146 0.42593899369239807 -0.5477944794777341"/>
			<geometry>
				<mesh filename="new_door_handle_space.obj"/>
			</geometry>
		</collision>
	</link>
	<joint name="joint_0" type="revolute">
		<origin xyz="-0.6430403380134146 -0.42593899369239807 0.5477944794777341"/>
		<axis xyz="0 -1 0"/>
		<child link="link_0"/>
		<parent link="link_1"/>
		<limit lower="0.0" upper="1.5707963267948966"/>
	</joint>
	<link name="link_1">
		<visual name="frame-2">
			<origin xyz="0 0 0"/>
			<geometry>
				<mesh filename="body.obj"/>
			</geometry>
		</visual>
		<collision>
			<origin xyz="0 0 0"/>
			<geometry>
				<mesh filename="body.obj"/>
			</geometry>
		</collision>
	</link>
	<joint name="joint_1" type="fixed">
		<origin rpy="1.570796326794897 0 -1.570796326794897" xyz="0 0 0"/>
		<child link="link_1"/>
		<parent link="base"/>
	</joint>

</robot>
